Traceback (most recent call last):
  File "/opt/hostedtoolcache/Python/3.10.4/x64/lib/python3.10/site-packages/jupyter_cache/executors/utils.py", line 51, in single_nb_execution
    executenb(
  File "/opt/hostedtoolcache/Python/3.10.4/x64/lib/python3.10/site-packages/nbclient/client.py", line 1204, in execute
    return NotebookClient(nb=nb, resources=resources, km=km, **kwargs).execute()
  File "/opt/hostedtoolcache/Python/3.10.4/x64/lib/python3.10/site-packages/nbclient/util.py", line 84, in wrapped
    return just_run(coro(*args, **kwargs))
  File "/opt/hostedtoolcache/Python/3.10.4/x64/lib/python3.10/site-packages/nbclient/util.py", line 62, in just_run
    return loop.run_until_complete(coro)
  File "/opt/hostedtoolcache/Python/3.10.4/x64/lib/python3.10/asyncio/base_events.py", line 646, in run_until_complete
    return future.result()
  File "/opt/hostedtoolcache/Python/3.10.4/x64/lib/python3.10/site-packages/nbclient/client.py", line 663, in async_execute
    await self.async_execute_cell(
  File "/opt/hostedtoolcache/Python/3.10.4/x64/lib/python3.10/site-packages/nbclient/client.py", line 965, in async_execute_cell
    await self._check_raise_for_error(cell, cell_index, exec_reply)
  File "/opt/hostedtoolcache/Python/3.10.4/x64/lib/python3.10/site-packages/nbclient/client.py", line 862, in _check_raise_for_error
    raise CellExecutionError.from_cell_and_msg(cell, exec_reply_content)
nbclient.exceptions.CellExecutionError: An error occurred while executing the following cell:
------------------
import pandas as pd
import numpy as np
import matplotlib.pyplot as plt
from sklearn.preprocessing import (StandardScaler, 
                                   PowerTransformer, 
                                   MinMaxScaler, 
                                   RobustScaler,
                                   MaxAbsScaler,
                                   QuantileTransformer)
import seaborn as sns
import utils
pd.options.display.precision = 2
pd.set_option('display.max_rows', 100)
pd.set_option("display.max.columns", None)
df = pd.read_pickle('12_tasks.pkl')
plt.style.use('bmh')
%load_ext autoreload
%autoreload 2
------------------

[0;31m---------------------------------------------------------------------------[0m
[0;31mFileNotFoundError[0m                         Traceback (most recent call last)
Input [0;32mIn [1][0m, in [0;36m<cell line: 15>[0;34m()[0m
[1;32m     13[0m pd[38;5;241m.[39mset_option([38;5;124m'[39m[38;5;124mdisplay.max_rows[39m[38;5;124m'[39m, [38;5;241m100[39m)
[1;32m     14[0m pd[38;5;241m.[39mset_option([38;5;124m"[39m[38;5;124mdisplay.max.columns[39m[38;5;124m"[39m, [38;5;28;01mNone[39;00m)
[0;32m---> 15[0m df [38;5;241m=[39m [43mpd[49m[38;5;241;43m.[39;49m[43mread_pickle[49m[43m([49m[38;5;124;43m'[39;49m[38;5;124;43m12_tasks.pkl[39;49m[38;5;124;43m'[39;49m[43m)[49m
[1;32m     16[0m plt[38;5;241m.[39mstyle[38;5;241m.[39muse([38;5;124m'[39m[38;5;124mbmh[39m[38;5;124m'[39m)
[1;32m     17[0m get_ipython()[38;5;241m.[39mrun_line_magic([38;5;124m'[39m[38;5;124mload_ext[39m[38;5;124m'[39m, [38;5;124m'[39m[38;5;124mautoreload[39m[38;5;124m'[39m)

File [0;32m/opt/hostedtoolcache/Python/3.10.4/x64/lib/python3.10/site-packages/pandas/io/pickle.py:187[0m, in [0;36mread_pickle[0;34m(filepath_or_buffer, compression, storage_options)[0m
[1;32m    124[0m [38;5;124;03m"""[39;00m
[1;32m    125[0m [38;5;124;03mLoad pickled pandas object (or any object) from file.[39;00m
[1;32m    126[0m 
[0;32m   (...)[0m
[1;32m    184[0m [38;5;124;03m4    4    9[39;00m
[1;32m    185[0m [38;5;124;03m"""[39;00m  [38;5;66;03m# noqa: E501[39;00m
[1;32m    186[0m excs_to_catch [38;5;241m=[39m ([38;5;167;01mAttributeError[39;00m, [38;5;167;01mImportError[39;00m, [38;5;167;01mModuleNotFoundError[39;00m, [38;5;167;01mTypeError[39;00m)
[0;32m--> 187[0m [38;5;28;01mwith[39;00m [43mget_handle[49m[43m([49m
[1;32m    188[0m [43m    [49m[43mfilepath_or_buffer[49m[43m,[49m
[1;32m    189[0m [43m    [49m[38;5;124;43m"[39;49m[38;5;124;43mrb[39;49m[38;5;124;43m"[39;49m[43m,[49m
[1;32m    190[0m [43m    [49m[43mcompression[49m[38;5;241;43m=[39;49m[43mcompression[49m[43m,[49m
[1;32m    191[0m [43m    [49m[43mis_text[49m[38;5;241;43m=[39;49m[38;5;28;43;01mFalse[39;49;00m[43m,[49m
[1;32m    192[0m [43m    [49m[43mstorage_options[49m[38;5;241;43m=[39;49m[43mstorage_options[49m[43m,[49m
[1;32m    193[0m [43m[49m[43m)[49m [38;5;28;01mas[39;00m handles:
[1;32m    194[0m 
[1;32m    195[0m     [38;5;66;03m# 1) try standard library Pickle[39;00m
[1;32m    196[0m     [38;5;66;03m# 2) try pickle_compat (older pandas version) to handle subclass changes[39;00m
[1;32m    197[0m     [38;5;66;03m# 3) try pickle_compat with latin-1 encoding upon a UnicodeDecodeError[39;00m
[1;32m    199[0m     [38;5;28;01mtry[39;00m:
[1;32m    200[0m         [38;5;66;03m# TypeError for Cython complaints about object.__new__ vs Tick.__new__[39;00m
[1;32m    201[0m         [38;5;28;01mtry[39;00m:

File [0;32m/opt/hostedtoolcache/Python/3.10.4/x64/lib/python3.10/site-packages/pandas/io/common.py:798[0m, in [0;36mget_handle[0;34m(path_or_buf, mode, encoding, compression, memory_map, is_text, errors, storage_options)[0m
[1;32m    789[0m         handle [38;5;241m=[39m [38;5;28mopen[39m(
[1;32m    790[0m             handle,
[1;32m    791[0m             ioargs[38;5;241m.[39mmode,
[0;32m   (...)[0m
[1;32m    794[0m             newline[38;5;241m=[39m[38;5;124m"[39m[38;5;124m"[39m,
[1;32m    795[0m         )
[1;32m    796[0m     [38;5;28;01melse[39;00m:
[1;32m    797[0m         [38;5;66;03m# Binary mode[39;00m
[0;32m--> 798[0m         handle [38;5;241m=[39m [38;5;28;43mopen[39;49m[43m([49m[43mhandle[49m[43m,[49m[43m [49m[43mioargs[49m[38;5;241;43m.[39;49m[43mmode[49m[43m)[49m
[1;32m    799[0m     handles[38;5;241m.[39mappend(handle)
[1;32m    801[0m [38;5;66;03m# Convert BytesIO or file objects passed with an encoding[39;00m

[0;31mFileNotFoundError[0m: [Errno 2] No such file or directory: '12_tasks.pkl'
FileNotFoundError: [Errno 2] No such file or directory: '12_tasks.pkl'

